2020-11-04 19:17:15,578 ERROR: Exception on /index [POST] [in /mnt/c/Users/obama/Desktop/Py-WebCS50/Flask/myflasky/venv/lib/python3.6/site-packages/flask/app.py:1892]
Traceback (most recent call last):
  File "/mnt/c/Users/obama/Desktop/Py-WebCS50/Flask/myflasky/venv/lib/python3.6/site-packages/sqlalchemy/engine/base.py", line 1277, in _execute_context
    cursor, statement, parameters, context
  File "/mnt/c/Users/obama/Desktop/Py-WebCS50/Flask/myflasky/venv/lib/python3.6/site-packages/sqlalchemy/engine/default.py", line 593, in do_execute
    cursor.execute(statement, parameters)
sqlite3.InterfaceError: Error binding parameter 3 - probably unsupported type.

The above exception was the direct cause of the following exception:

Traceback (most recent call last):
  File "/mnt/c/Users/obama/Desktop/Py-WebCS50/Flask/myflasky/venv/lib/python3.6/site-packages/flask/app.py", line 2447, in wsgi_app
    response = self.full_dispatch_request()
  File "/mnt/c/Users/obama/Desktop/Py-WebCS50/Flask/myflasky/venv/lib/python3.6/site-packages/flask/app.py", line 1952, in full_dispatch_request
    rv = self.handle_user_exception(e)
  File "/mnt/c/Users/obama/Desktop/Py-WebCS50/Flask/myflasky/venv/lib/python3.6/site-packages/flask/app.py", line 1821, in handle_user_exception
    reraise(exc_type, exc_value, tb)
  File "/mnt/c/Users/obama/Desktop/Py-WebCS50/Flask/myflasky/venv/lib/python3.6/site-packages/flask/_compat.py", line 39, in reraise
    raise value
  File "/mnt/c/Users/obama/Desktop/Py-WebCS50/Flask/myflasky/venv/lib/python3.6/site-packages/flask/app.py", line 1950, in full_dispatch_request
    rv = self.dispatch_request()
  File "/mnt/c/Users/obama/Desktop/Py-WebCS50/Flask/myflasky/venv/lib/python3.6/site-packages/flask/app.py", line 1936, in dispatch_request
    return self.view_functions[rule.endpoint](**req.view_args)
  File "/mnt/c/Users/obama/Desktop/Py-WebCS50/Flask/myflasky/venv/lib/python3.6/site-packages/flask_login/utils.py", line 272, in decorated_view
    return func(*args, **kwargs)
  File "/mnt/c/Users/obama/Desktop/Py-WebCS50/Flask/myflasky/app/routes.py", line 34, in index
    db.session.commit()
  File "/mnt/c/Users/obama/Desktop/Py-WebCS50/Flask/myflasky/venv/lib/python3.6/site-packages/sqlalchemy/orm/scoping.py", line 163, in do
    return getattr(self.registry(), name)(*args, **kwargs)
  File "/mnt/c/Users/obama/Desktop/Py-WebCS50/Flask/myflasky/venv/lib/python3.6/site-packages/sqlalchemy/orm/session.py", line 1042, in commit
    self.transaction.commit()
  File "/mnt/c/Users/obama/Desktop/Py-WebCS50/Flask/myflasky/venv/lib/python3.6/site-packages/sqlalchemy/orm/session.py", line 504, in commit
    self._prepare_impl()
  File "/mnt/c/Users/obama/Desktop/Py-WebCS50/Flask/myflasky/venv/lib/python3.6/site-packages/sqlalchemy/orm/session.py", line 483, in _prepare_impl
    self.session.flush()
  File "/mnt/c/Users/obama/Desktop/Py-WebCS50/Flask/myflasky/venv/lib/python3.6/site-packages/sqlalchemy/orm/session.py", line 2523, in flush
    self._flush(objects)
  File "/mnt/c/Users/obama/Desktop/Py-WebCS50/Flask/myflasky/venv/lib/python3.6/site-packages/sqlalchemy/orm/session.py", line 2664, in _flush
    transaction.rollback(_capture_exception=True)
  File "/mnt/c/Users/obama/Desktop/Py-WebCS50/Flask/myflasky/venv/lib/python3.6/site-packages/sqlalchemy/util/langhelpers.py", line 69, in __exit__
    exc_value, with_traceback=exc_tb,
  File "/mnt/c/Users/obama/Desktop/Py-WebCS50/Flask/myflasky/venv/lib/python3.6/site-packages/sqlalchemy/util/compat.py", line 182, in raise_
    raise exception
  File "/mnt/c/Users/obama/Desktop/Py-WebCS50/Flask/myflasky/venv/lib/python3.6/site-packages/sqlalchemy/orm/session.py", line 2624, in _flush
    flush_context.execute()
  File "/mnt/c/Users/obama/Desktop/Py-WebCS50/Flask/myflasky/venv/lib/python3.6/site-packages/sqlalchemy/orm/unitofwork.py", line 422, in execute
    rec.execute(self)
  File "/mnt/c/Users/obama/Desktop/Py-WebCS50/Flask/myflasky/venv/lib/python3.6/site-packages/sqlalchemy/orm/unitofwork.py", line 589, in execute
    uow,
  File "/mnt/c/Users/obama/Desktop/Py-WebCS50/Flask/myflasky/venv/lib/python3.6/site-packages/sqlalchemy/orm/persistence.py", line 245, in save_obj
    insert,
  File "/mnt/c/Users/obama/Desktop/Py-WebCS50/Flask/myflasky/venv/lib/python3.6/site-packages/sqlalchemy/orm/persistence.py", line 1136, in _emit_insert_statements
    statement, params
  File "/mnt/c/Users/obama/Desktop/Py-WebCS50/Flask/myflasky/venv/lib/python3.6/site-packages/sqlalchemy/engine/base.py", line 1011, in execute
    return meth(self, multiparams, params)
  File "/mnt/c/Users/obama/Desktop/Py-WebCS50/Flask/myflasky/venv/lib/python3.6/site-packages/sqlalchemy/sql/elements.py", line 298, in _execute_on_connection
    return connection._execute_clauseelement(self, multiparams, params)
  File "/mnt/c/Users/obama/Desktop/Py-WebCS50/Flask/myflasky/venv/lib/python3.6/site-packages/sqlalchemy/engine/base.py", line 1130, in _execute_clauseelement
    distilled_params,
  File "/mnt/c/Users/obama/Desktop/Py-WebCS50/Flask/myflasky/venv/lib/python3.6/site-packages/sqlalchemy/engine/base.py", line 1317, in _execute_context
    e, statement, parameters, cursor, context
  File "/mnt/c/Users/obama/Desktop/Py-WebCS50/Flask/myflasky/venv/lib/python3.6/site-packages/sqlalchemy/engine/base.py", line 1511, in _handle_dbapi_exception
    sqlalchemy_exception, with_traceback=exc_info[2], from_=e
  File "/mnt/c/Users/obama/Desktop/Py-WebCS50/Flask/myflasky/venv/lib/python3.6/site-packages/sqlalchemy/util/compat.py", line 182, in raise_
    raise exception
  File "/mnt/c/Users/obama/Desktop/Py-WebCS50/Flask/myflasky/venv/lib/python3.6/site-packages/sqlalchemy/engine/base.py", line 1277, in _execute_context
    cursor, statement, parameters, context
  File "/mnt/c/Users/obama/Desktop/Py-WebCS50/Flask/myflasky/venv/lib/python3.6/site-packages/sqlalchemy/engine/default.py", line 593, in do_execute
    cursor.execute(statement, parameters)
sqlalchemy.exc.InterfaceError: (sqlite3.InterfaceError) Error binding parameter 3 - probably unsupported type.
[SQL: INSERT INTO post (body, timestamp, user_id, language) VALUES (?, ?, ?, ?)]
[parameters: ('xin ch√†o\r\n', '2020-11-04 12:17:15.577366', 1, <googletrans.models.Detected object at 0x7fe6347dd2b0>)]
(Background on this error at: http://sqlalche.me/e/13/rvf5)
2020-11-04 19:18:58,452 INFO: My flask startup [in /mnt/c/Users/obama/Desktop/Py-WebCS50/Flask/myflasky/app/__init__.py:53]
2020-11-04 19:19:05,833 ERROR: Exception on /index [POST] [in /mnt/c/Users/obama/Desktop/Py-WebCS50/Flask/myflasky/venv/lib/python3.6/site-packages/flask/app.py:1892]
Traceback (most recent call last):
  File "/mnt/c/Users/obama/Desktop/Py-WebCS50/Flask/myflasky/venv/lib/python3.6/site-packages/flask/app.py", line 2447, in wsgi_app
    response = self.full_dispatch_request()
  File "/mnt/c/Users/obama/Desktop/Py-WebCS50/Flask/myflasky/venv/lib/python3.6/site-packages/flask/app.py", line 1952, in full_dispatch_request
    rv = self.handle_user_exception(e)
  File "/mnt/c/Users/obama/Desktop/Py-WebCS50/Flask/myflasky/venv/lib/python3.6/site-packages/flask/app.py", line 1821, in handle_user_exception
    reraise(exc_type, exc_value, tb)
  File "/mnt/c/Users/obama/Desktop/Py-WebCS50/Flask/myflasky/venv/lib/python3.6/site-packages/flask/_compat.py", line 39, in reraise
    raise value
  File "/mnt/c/Users/obama/Desktop/Py-WebCS50/Flask/myflasky/venv/lib/python3.6/site-packages/flask/app.py", line 1950, in full_dispatch_request
    rv = self.dispatch_request()
  File "/mnt/c/Users/obama/Desktop/Py-WebCS50/Flask/myflasky/venv/lib/python3.6/site-packages/flask/app.py", line 1936, in dispatch_request
    return self.view_functions[rule.endpoint](**req.view_args)
  File "/mnt/c/Users/obama/Desktop/Py-WebCS50/Flask/myflasky/venv/lib/python3.6/site-packages/flask_login/utils.py", line 272, in decorated_view
    return func(*args, **kwargs)
  File "/mnt/c/Users/obama/Desktop/Py-WebCS50/Flask/myflasky/app/routes.py", line 29, in index
    language = tran.detect('form.post.data')
  File "/mnt/c/Users/obama/Desktop/Py-WebCS50/Flask/myflasky/venv/lib/python3.6/site-packages/googletrans/client.py", line 255, in detect
    data = self._translate(text, 'en', 'auto', kwargs)
  File "/mnt/c/Users/obama/Desktop/Py-WebCS50/Flask/myflasky/venv/lib/python3.6/site-packages/googletrans/client.py", line 78, in _translate
    token = self.token_acquirer.do(text)
  File "/mnt/c/Users/obama/Desktop/Py-WebCS50/Flask/myflasky/venv/lib/python3.6/site-packages/googletrans/gtoken.py", line 194, in do
    self._update()
  File "/mnt/c/Users/obama/Desktop/Py-WebCS50/Flask/myflasky/venv/lib/python3.6/site-packages/googletrans/gtoken.py", line 62, in _update
    code = self.RE_TKK.search(r.text).group(1).replace('var ', '')
AttributeError: 'NoneType' object has no attribute 'group'
2020-11-04 19:19:57,027 INFO: My flask startup [in /mnt/c/Users/obama/Desktop/Py-WebCS50/Flask/myflasky/app/__init__.py:53]
